---- Error : HTTPSConnectionPool(host='mp.weixin.qq.com', port=443): Max retries exceeded with url: /cgi-bin/appmsg?token=1217253842&lang=zh_CN&f=json&ajax=1&random=0.8747064370723439&action=list_ex&begin=345&count=5&query=&fakeid=MjgzMTAwODI0MA%3D%3D&type=9 (Caused by SSLError(SSLError("bad handshake: SysCallError(-1, 'Unexpected EOF')",),))
Traceback (most recent call last):
  File "/Users/yuhangzhan/anaconda3/lib/python3.6/site-packages/urllib3/contrib/pyopenssl.py", line 444, in wrap_socket
    cnx.do_handshake()
  File "/Users/yuhangzhan/anaconda3/lib/python3.6/site-packages/OpenSSL/SSL.py", line 1907, in do_handshake
    self._raise_ssl_error(self._ssl, result)
  File "/Users/yuhangzhan/anaconda3/lib/python3.6/site-packages/OpenSSL/SSL.py", line 1632, in _raise_ssl_error
    raise SysCallError(-1, "Unexpected EOF")
OpenSSL.SSL.SysCallError: (-1, 'Unexpected EOF')

During handling of the above exception, another exception occurred:

Traceback (most recent call last):
  File "/Users/yuhangzhan/anaconda3/lib/python3.6/site-packages/urllib3/connectionpool.py", line 594, in urlopen
    self._prepare_proxy(conn)
  File "/Users/yuhangzhan/anaconda3/lib/python3.6/site-packages/urllib3/connectionpool.py", line 815, in _prepare_proxy
    conn.connect()
  File "/Users/yuhangzhan/anaconda3/lib/python3.6/site-packages/urllib3/connection.py", line 356, in connect
    ssl_context=context)
  File "/Users/yuhangzhan/anaconda3/lib/python3.6/site-packages/urllib3/util/ssl_.py", line 359, in ssl_wrap_socket
    return context.wrap_socket(sock, server_hostname=server_hostname)
  File "/Users/yuhangzhan/anaconda3/lib/python3.6/site-packages/urllib3/contrib/pyopenssl.py", line 450, in wrap_socket
    raise ssl.SSLError('bad handshake: %r' % e)
ssl.SSLError: ("bad handshake: SysCallError(-1, 'Unexpected EOF')",)

During handling of the above exception, another exception occurred:

Traceback (most recent call last):
  File "/Users/yuhangzhan/anaconda3/lib/python3.6/site-packages/requests/adapters.py", line 445, in send
    timeout=timeout
  File "/Users/yuhangzhan/anaconda3/lib/python3.6/site-packages/urllib3/connectionpool.py", line 638, in urlopen
    _stacktrace=sys.exc_info()[2])
  File "/Users/yuhangzhan/anaconda3/lib/python3.6/site-packages/urllib3/util/retry.py", line 398, in increment
    raise MaxRetryError(_pool, url, error or ResponseError(cause))
urllib3.exceptions.MaxRetryError: HTTPSConnectionPool(host='mp.weixin.qq.com', port=443): Max retries exceeded with url: /cgi-bin/appmsg?token=1217253842&lang=zh_CN&f=json&ajax=1&random=0.8747064370723439&action=list_ex&begin=345&count=5&query=&fakeid=MjgzMTAwODI0MA%3D%3D&type=9 (Caused by SSLError(SSLError("bad handshake: SysCallError(-1, 'Unexpected EOF')",),))

During handling of the above exception, another exception occurred:

Traceback (most recent call last):
  File "/Users/yuhangzhan/Github/newspush/wechat-crawler/mp_wx_crawler.py", line 225, in <module>
    get_content_msg(query, path, token, fakeid, header, cookies)
  File "/Users/yuhangzhan/Github/newspush/wechat-crawler/mp_wx_crawler.py", line 202, in get_content_msg
    headers=header
  File "/Users/yuhangzhan/anaconda3/lib/python3.6/site-packages/requests/api.py", line 72, in get
    return request('get', url, params=params, **kwargs)
  File "/Users/yuhangzhan/anaconda3/lib/python3.6/site-packages/requests/api.py", line 58, in request
    return session.request(method=method, url=url, **kwargs)
  File "/Users/yuhangzhan/anaconda3/lib/python3.6/site-packages/requests/sessions.py", line 512, in request
    resp = self.send(prep, **send_kwargs)
  File "/Users/yuhangzhan/anaconda3/lib/python3.6/site-packages/requests/sessions.py", line 622, in send
    r = adapter.send(request, **kwargs)
  File "/Users/yuhangzhan/anaconda3/lib/python3.6/site-packages/requests/adapters.py", line 511, in send
    raise SSLError(e, request=request)
requests.exceptions.SSLError: HTTPSConnectionPool(host='mp.weixin.qq.com', port=443): Max retries exceeded with url: /cgi-bin/appmsg?token=1217253842&lang=zh_CN&f=json&ajax=1&random=0.8747064370723439&action=list_ex&begin=345&count=5&query=&fakeid=MjgzMTAwODI0MA%3D%3D&type=9 (Caused by SSLError(SSLError("bad handshake: SysCallError(-1, 'Unexpected EOF')",),))